Workbook

Sheet 001-EC-HR-HRBP-Job Information 
AB1: Skill ใส่ช่องนี้นะ | AI1: กะ 1 | AL1: กะ 2 | AO1: กะ 3
A2: No. | B2: User ID (Job Information) | C2: ID card Salutation (TH) | D2: First Name (Local) | E2: Last Name (Local) | F2: ชื่อ นามสกุล | G2: First Name (EN) (Personal Information) | H2: Last Name (EN) (Personal Information) | I2: Username | J2: Employment Status | K2: CAL_HireDate | L2: Name (Employment Type) | M2: Probation | N2: Pass Probation | O2: Expect_Pass_Probation_DT | P2: Pass_Probation_DT | Q2: Code (Position) | R2: Title (Position) | S2: หน่วยงาน | T2: Name (Section) | U2: District (EN) | V2: Province (EN) | W2: Nationality Country/Region | Y2: Step | Z2: skill_metrix | AA2: หา ค.สามารถ | AB2: SKILL CF | AC2: วันหยุด ประจำสัปดาห์ | AD2: หมายเหตุ | AF2: อยู่กะไหน | AG2: สลับกะวันไหน | AH2: สลับยังไง | AI2: เวลาเริ่ม | AJ2: เวลาออก | AK2: OT+- | AL2: เวลาเริ่ม | AM2: เวลาออก | AN2: OT+- | AO2: เวลาเริ่ม | AP2: เวลาออก | AQ2: OT+-
A3: 21 | B3: 10339980 | C3: นางสาว | D3: สุดารัตน์ | E3: สิงห์กล้า | F3: =D3&" "&E3 -> สุดารัตน์ สิงห์กล้า | G3: SUDARAT | H3: SINGKLA | I3: SUDARAT.SIG | J3: ทำงานอยู่ | K3: 19/5/2018 | L3: รายเดือน | M3: ใช่ | N3: ใช่ | O3: 15/9/2018 | P3: 15/9/2018 | Q3: 10405224 | R3: ผู้ปฏิบัติการ (รับสินค้า (Confirm)) | S3: งานคลังสินค้า | T3: โรงงานชำแหละและตัดแต่งสุกรพระพุทธบาท | U3: Phra Phutthabat | V3: Saraburi | W3: ไทย | X3: 1 | Y3: คลัง | AB3: picking | AC3: อ | AF3: กะ1 | AI3: 0.33333333 | AJ3: 0.70833333 | AK3: 0.83333333
A4: 44 | B4: 10386416 | C4: นาง | D4: โชติกา | E4: นาคสุทธิ์ | F4: =D4&" "&E4 -> โชติกา นาคสุทธิ์ | G4: CHOTIKA | H4: NAKSUD | I4: 10386416 | J4: ทำงานอยู่ | K4: 18/10/2019 | L4: รายวัน | M4: ใช่ | N4: ใช่ | O4: 14/2/2020 | P4: 14/2/2020 | Q4: 10358486 | R4: ผู้ปฏิบัติการ (จ่ายชิ้นส่วน-D) | S4: งานคลังสินค้า | T4: โรงงานชำแหละและตัดแต่งสุกรพระพุทธบาท | U4: Phra Phutthabat | V4: Saraburi | W4: ไทย | X4: 1 | Y4: คลัง | AB4: picking | AC4: พฤ | AF4: กะ1 | AI4: 0.33333333 | AJ4: 0.70833333 | AK4: 0.83333333
A5: 50 | B5: 10393693 | C5: นางสาว | D5: ธมนพัชร์ | E5: วงศ์สุนันท์ | F5: =D5&" "&E5 -> ธมนพัชร์ วงศ์สุนันท์ | G5: THAMONPACH | H5: WONGSUNAN | I5: THAMONPACH.WON | J5: ทำงานอยู่ | K5: 43832 | L5: รายเดือน | M5: ใช่ | N5: ใช่ | O5: 30/5/2020 | P5: 30/5/2020 | Q5: 10405224 | R5: ผู้ปฏิบัติการ (รับสินค้า (Confirm)) | S5: งานคลังสินค้า | T5: โรงงานชำแหละและตัดแต่งสุกรพระพุทธบาท | U5: Phra Phutthabat | V5: Saraburi | W5: ไทย | X5: 1 | Y5: คลัง | AB5: picking | AC5: ศ | AF5: กะ2 | AL5: 0.83333333 | AM5: 0.20833333 | AN5: 0.33333333
A6: 141 | B6: 10558877 | C6: นางสาว | D6: ณัฐพร | E6: ทัพศาสตร์ | F6: =D6&" "&E6 -> ณัฐพร ทัพศาสตร์ | G6: NATTHAPHON | H6: TASAT | I6: 10558877 | J6: ทำงานอยู่ | K6: 44932 | L6: รายวัน | M6: ใช่ | N6: ใช่ | O6: 28/9/2023 | P6: 28/9/2023 | Q6: 10405192 | R6: ผู้ปฏิบัติการ (รับสินค้า (Confirm)-D) | S6: งานคลังสินค้า | T6: โรงงานชำแหละและตัดแต่งสุกรพระพุทธบาท | U6: Phra Phutthabat | V6: Saraburi | W6: ไทย | X6: 1 | Y6: คลัง | AB6: picking | AC6: จ | AF6: กะ2 | AL6: 0.83333333 | AM6: 0.20833333 | AN6: 0.33333333
A7: 233 | B7: 10653656 | C7: นางสาว | D7: สรีรัญ | E7: วันศิริ | F7: =D7&" "&E7 -> สรีรัญ วันศิริ | G7: SAREERAN | H7: WANSIRI | I7: 10653656 | J7: ทำงานอยู่ | K7: 45664 | L7: รายวัน | M7: ใช่ | N7: ใช่ | O7: 28/10/2025 | P7: 28/10/2025 | Q7: 10358486 | R7: ผู้ปฏิบัติการ (จ่ายชิ้นส่วน-D) | S7: งานคลังสินค้า | T7: โรงงานชำแหละและตัดแต่งสุกรพระพุทธบาท | U7: Phra Phutthabat | V7: Saraburi | W7: ไทย | X7: 1 | Y7: คลัง | AB7: เครื่องใน | AC7: อา | AF7: กะ1 | AI7: 0.33333333 | AJ7: 0.70833333 | AK7: 0.83333333
A8: 356 | B8: 10680258 | C8: นาย | D8: วัฒธนศิล | E8: บุญสา | F8: =D8&" "&E8 -> วัฒธนศิล บุญสา | G8: WATTANASIN | H8: BOONSA | I8: 10680258 | J8: ทำงานอยู่ | K8: 19/1/2026 | L8: รายวัน | M8: ใช่ | N8: ไม่ใช่ | O8: 18/5/2026 | P8: // | Q8: 10358473 | R8: ผู้ปฏิบัติการ (รับ-จ่ายเครื่องใน-D) | S8: งานคลังสินค้า | T8: โรงงานชำแหละและตัดแต่งสุกรพระพุทธบาท | U8: Phra Phutthabat | V8: Saraburi | W8: ไทย | X8: 1 | Y8: คลัง | AB8: เครื่องใน | AC8: พระ | AF8: กะ1 | AI8: 0.33333333 | AJ8: 0.70833333 | AK8: 0.83333333
A9: 258 | B9: 10658400 | C9: นาย | D9: วรภพ | E9: ชูเกาะ | F9: =D9&" "&E9 -> วรภพ ชูเกาะ | G9: WORAPHOP | H9: CHUKO | I9: 10658400 | J9: ทำงานอยู่ | K9: 45665 | L9: รายวัน | M9: ใช่ | N9: ใช่ | O9: 28/11/2025 | P9: 28/11/2025 | Q9: 10358473 | R9: ผู้ปฏิบัติการ (รับ-จ่ายเครื่องใน-D) | S9: งานคลังสินค้า | T9: โรงงานชำแหละและตัดแต่งสุกรพระพุทธบาท | U9: Phra Phutthabat | V9: Saraburi | W9: ไทย | X9: 1 | Y9: คลัง | AB9: เครื่องใน | AC9: พฤ | AF9: กะ1 | AI9: 0.33333333 | AJ9: 0.70833333 | AK9: 0.83333333
A10: 104 | B10: 10510959 | C10: นาย | D10: ธันธร | E10: ทัพศาสตร์ | F10: =D10&" "&E10 -> ธันธร ทัพศาสตร์ | G10: THANTHON | H10: THAPSAT | I10: 10510959 | J10: ทำงานอยู่ | K10: 44898 | L10: รายวัน | M10: ใช่ | N10: ใช่ | O10: 44811 | P10: 44811 | Q10: 10358473 | R10: ผู้ปฏิบัติการ (รับ-จ่ายเครื่องใน-D) | S10: งานคลังสินค้า | T10: โรงงานชำแหละและตัดแต่งสุกรพระพุทธบาท | U10: Phra Phutthabat | V10: Saraburi | W10: ไทย | X10: 1 | Y10: คลัง | AB10: เครื่องใน | AC10: จ | AF10: กะ1 | AI10: 0.33333333 | AJ10: 0.70833333 | AK10: 0.83333333
A11: 227 | B11: 10652118 | C11: นาย | D11: คณัสนันท์ | E11: ธรรมโชติ | F11: =D11&" "&E11 -> คณัสนันท์ ธรรมโชติ | G11: KHANATSANAN | H11: THAMMACHOT | I11: 10652118 | J11: ทำงานอยู่ | K11: 16/6/2025 | L11: รายวัน | M11: ใช่ | N11: ใช่ | O11: 13/10/2025 | P11: 13/10/2025 | Q11: 10358473 | R11: ผู้ปฏิบัติการ (รับ-จ่ายเครื่องใน-D) | S11: งานคลังสินค้า | T11: โรงงานชำแหละและตัดแต่งสุกรพระพุทธบาท | U11: Phra Phutthabat | V11: Saraburi | W11: ไทย | X11: 1 | Y11: คลัง | AB11: เครื่องใน | AC11: อ | AF11: กะ1 | AI11: 0.33333333 | AJ11: 0.70833333 | AK11: 0.83333333
A12: 67 | B12: 10415060 | C12: นาง | D12: สุวิมล | E12: พงษ์เถื่อน | F12: =D12&" "&E12 -> สุวิมล พงษ์เถื่อน | G12: SUWIMOL | H12: PONGTHEUN | I12: 10415060 | J12: ทำงานอยู่ | K12: 43994 | L12: รายวัน | M12: ใช่ | N12: ใช่ | O12: 44290 | P12: 44290 | Q12: 10405186 | R12: ผู้ปฏิบัติการ (รับ-จ่ายหัว-D) | S12: งานคลังสินค้า | T12: โรงงานชำแหละและตัดแต่งสุกรพระพุทธบาท | U12: Phra Phutthabat | V12: Saraburi | W12: ไทย | X12: 1 | Y12: คลัง | AB12: เครื่องใน | AC12: จ | AF12: กะ2 | AL12: 0.79166667 | AM12: 0.16666667 | AN12: 0.29166667
A13: 116 | B13: 10532723 | C13: นาย | D13: สุวรรณ์ | E13: คำมี | F13: =D13&" "&E13 -> สุวรรณ์ คำมี | G13: SUWAN | H13: KAMMEE | I13: 10532723 | J13: ทำงานอยู่ | K13: 44603 | L13: รายวัน | M13: ใช่ | N13: ใช่ | O13: 44929 | P13: 44929 | Q13: 10358473 | R13: ผู้ปฏิบัติการ (รับ-จ่ายเครื่องใน-D) | S13: งานคลังสินค้า | T13: โรงงานชำแหละและตัดแต่งสุกรพระพุทธบาท | U13: Phra Phutthabat | V13: Saraburi | W13: ไทย | X13: 1 | Y13: คลัง | AB13: เครื่องใน | AC13: พฤ | AF13: กะ2 | AL13: 0.79166667 | AM13: 0.16666667 | AN13: 0.29166667
A14: 140 | B14: 10556230 | C14: นาย | D14: สมศักดิ์ | E14: หนูทองแดง | F14: =D14&" "&E14 -> สมศักดิ์ หนูทองแดง | G14: SOMSAK | H14: NUTHONGDAENG | I14: 10556230 | J14: ทำงานอยู่ | K14: 16/5/2023 | L14: รายวัน | M14: ใช่ | N14: ใช่ | O14: 45269 | P14: 45269 | Q14: 10358473 | R14: ผู้ปฏิบัติการ (รับ-จ่ายเครื่องใน-D) | S14: งานคลังสินค้า | T14: โรงงานชำแหละและตัดแต่งสุกรพระพุทธบาท | U14: Phra Phutthabat | V14: Saraburi | W14: ไทย | X14: 1 | Y14: คลัง | AB14: เครื่องใน | AC14: อ | AF14: กะ2 | AL14: 0.79166667 | AM14: 0.16666667 | AN14: 0.29166667
A15: 38 | B15: 10366440 | C15: นาย | D15: พิชิต | E15: บุษฎา | F15: =D15&" "&E15 -> พิชิต บุษฎา | G15: PHICHIT | H15: BOODSADA | I15: PHICHIT.BOO | J15: ทำงานอยู่ | K15: 43469 | L15: รายเดือน | M15: ใช่ | N15: ใช่ | O15: 29/7/2019 | P15: 29/7/2019 | Q15: 10405222 | R15: ผู้ปฏิบัติการ (รับ-จ่ายหัว) | S15: งานคลังสินค้า | T15: โรงงานชำแหละและตัดแต่งสุกรพระพุทธบาท | U15: Phra Phutthabat | V15: Saraburi | W15: ไทย | X15: 1 | Y15: คลัง | AB15: เครื่องใน | AC15: พ | AF15: กะ2 | AL15: 0.79166667 | AM15: 0.16666667 | AN15: 0.29166667
A16: 255 | B16: 10658249 | C16: นาย | D16: นครินทร์ | E16: มะลิทอง | F16: =D16&" "&E16 -> นครินทร์ มะลิทอง | G16: NAKARIN | H16: MALITHONG | I16: 10658249 | J16: ทำงานอยู่ | K16: 45665 | L16: รายวัน | M16: ใช่ | N16: ใช่ | O16: 28/11/2025 | P16: 28/11/2025 | Q16: 10405186 | R16: ผู้ปฏิบัติการ (รับ-จ่ายหัว-D) | S16: งานคลังสินค้า | T16: โรงงานชำแหละและตัดแต่งสุกรพระพุทธบาท | U16: Phra Phutthabat | V16: Saraburi | W16: ไทย | X16: 1 | Y16: คลัง | AB16: เครื่องใน | AC16: อา | AF16: กะ2 | AL16: 0.79166667 | AM16: 0.16666667 | AN16: 0.29166667
B17: 10567228 | D17: อริย | E17: เสนาะสลุง | S17: งานคลังสินค้า | AB17: จ่ายชิ้นส่วนกะ | AC17: อา | AF17: กะ1 | AI17: 0.33333333 | AJ17: 0.70833333 | AK17: 0.83333333
A18: 353 | B18: 10680226 | C18: นาย | D18: อดิศักดิ์ | E18: ผาสุขธรรม | F18: =D18&" "&E18 -> อดิศักดิ์ ผาสุขธรรม | G18: ADISAK | H18: PARSUKTHAM | I18: 10680226 | J18: ทำงานอยู่ | K18: 19/1/2026 | L18: รายวัน | M18: ใช่ | N18: ไม่ใช่ | O18: 18/5/2026 | P18: // | Q18: 10358476 | R18: ผู้ปฎิบัติการ (จ่ายชิ้นส่วน-D) | S18: งานคลังสินค้า | T18: โรงงานชำแหละและตัดแต่งสุกรพระพุทธบาท | U18: Phra Phutthabat | V18: Saraburi | W18: ไทย | X18: 1 | Y18: คลัง | AB18: จ่ายชิ้นส่วนกะ | AC18: อา | AF18: กะ1 | AI18: 0.33333333 | AJ18: 0.70833333 | AK18: 0.83333333
B19: 10596679 | D19: สัญญา | E19: อนุสิทธิ์ | S19: งานคลังสินค้า | AB19: จ่ายชิ้นส่วนกะ | AC19: พ | AF19: กะ1 | AI19: 0.33333333 | AJ19: 0.70833333 | AK19: 0.83333333
A20: 72 | B20: 10417544 | C20: นาย | D20: สราวุธ | E20: โต้ตอบ | F20: =D20&" "&E20 -> สราวุธ โต้ตอบ | G20: SARAWUT | H20: TOTOB | I20: 10417544 | J20: ทำงานอยู่ | K20: 20/1/2021 | L20: รายวัน | M20: ใช่ | N20: ใช่ | O20: 19/5/2021 | P20: 19/5/2021 | Q20: 10358486 | R20: ผู้ปฏิบัติการ (จ่ายชิ้นส่วน-D) | S20: งานคลังสินค้า | T20: โรงงานชำแหละและตัดแต่งสุกรพระพุทธบาท | U20: Phra Phutthabat | V20: Saraburi | W20: ไทย | X20: 1 | Y20: คลัง | AB20: จ่ายชิ้นส่วนกะ | AC20: ศ | AF20: กะ1 | AI20: 0.33333333 | AJ20: 0.70833333 | AK20: 0.83333333
A21: 239 | B21: 10653715 | C21: นาย | D21: ยุทธนา | E21: ภูทอง | F21: =D21&" "&E21 -> ยุทธนา ภูทอง | G21: YUTTHNA | H21: PHUTHONG | I21: 10653715 | J21: ทำงานอยู่ | K21: 45664 | L21: รายวัน | M21: ใช่ | N21: ใช่ | O21: 28/10/2025 | P21: 28/10/2025 | Q21: 10358486 | R21: ผู้ปฏิบัติการ (จ่ายชิ้นส่วน-D) | S21: งานคลังสินค้า | T21: โรงงานชำแหละและตัดแต่งสุกรพระพุทธบาท | U21: Phra Phutthabat | V21: Saraburi | W21: ไทย | X21: 1 | Y21: คลัง | AB21: จ่ายชิ้นส่วนกะ | AC21: พ | AF21: กะ1 | AI21: 0.33333333 | AJ21: 0.70833333 | AK21: 0.83333333
A22: 204 | B22: 10634220 | C22: นางสาว | D22: ปวริศา | E22: ภิรมยา | F22: =D22&" "&E22 -> ปวริศา ภิรมยา | G22: POWARISA | H22: PHIROMYA | I22: 10634220 | J22: ทำงานอยู่ | K22: 19/1/2025 | L22: รายวัน | M22: ใช่ | N22: ใช่ | O22: 18/5/2025 | P22: 18/5/2025 | Q22: 10358486 | R22: ผู้ปฏิบัติการ (จ่ายชิ้นส่วน-D) | S22: งานคลังสินค้า | T22: โรงงานชำแหละและตัดแต่งสุกรพระพุทธบาท | U22: Phra Phutthabat | V22: Saraburi | W22: ไทย | X22: 1 | Y22: คลัง | AB22: จ่ายชิ้นส่วนกะ | AC22: จ | AF22: กะ1 | AI22: 0.33333333 | AJ22: 0.70833333 | AK22: 0.83333333
A23: 217 | B23: 10643182 | C23: นาย | D23: นัฐพงษ์ | E23: ไหวพริบ | F23: =D23&" "&E23 -> นัฐพงษ์ ไหวพริบ | G23: NATTAPONG | H23: HWAIPRIP | I23: 10643182 | J23: ทำงานอยู่ | K23: 45661 | L23: รายวัน | M23: ใช่ | N23: ใช่ | O23: 29/7/2025 | P23: 29/7/2025 | Q23: 10358486 | R23: ผู้ปฏิบัติการ (จ่ายชิ้นส่วน-D) | S23: งานคลังสินค้า | T23: โรงงานชำแหละและตัดแต่งสุกรพระพุทธบาท | U23: Phra Phutthabat | V23: Saraburi | W23: ไทย | X23: 1 | Y23: คลัง | AB23: จ่ายชิ้นส่วนกะ | AC23: อ | AF23: กะ1 | AI23: 0.33333333 | AJ23: 0.70833333 | AK23: 0.83333333
A24: 212 | B24: 10641135 | C24: นาย | D24: ทรงยศ | E24: เกิดขาว | F24: =D24&" "&E24 -> ทรงยศ เกิดขาว | G24: SONGYOT | H24: KOEDKHAO | I24: 10641135 | J24: ทำงานอยู่ | K24: 17/3/2025 | L24: รายวัน | M24: ใช่ | N24: ใช่ | O24: 14/7/2025 | P24: 14/7/2025 | Q24: 10358486 | R24: ผู้ปฏิบัติการ (จ่ายชิ้นส่วน-D) | S24: งานคลังสินค้า | T24: โรงงานชำแหละและตัดแต่งสุกรพระพุทธบาท | U24: Phra Phutthabat | V24: Saraburi | W24: ไทย | X24: 1 | Y24: คลัง | AB24: จ่ายชิ้นส่วนกะ | AC24: พฤ | AF24: กะ1 | AI24: 0.33333333 | AJ24: 0.70833333 | AK24: 0.83333333
A25: 229 | B25: 10652130 | C25: นาย | D25: ชยุต | E25: ธาทนะปรีดา | F25: =D25&" "&E25 -> ชยุต ธาทนะปรีดา | G25: CHAYUT | H25: TATANAPREDA | I25: 10652130 | J25: ทำงานอยู่ | K25: 16/6/2025 | L25: รายวัน | M25: ใช่ | N25: ใช่ | O25: 13/10/2025 | P25: 13/10/2025 | Q25: 10358486 | R25: ผู้ปฏิบัติการ (จ่ายชิ้นส่วน-D) | S25: งานคลังสินค้า | T25: โรงงานชำแหละและตัดแต่งสุกรพระพุทธบาท | U25: Phra Phutthabat | V25: Saraburi | W25: ไทย | X25: 1 | Y25: คลัง | AB25: จ่ายชิ้นส่วนกะ | AC25: พฤ | AF25: กะ1 | AI25: 0.33333333 | AJ25: 0.70833333 | AK25: 0.83333333
A26: 352 | B26: 10680215 | C26: นาย | D26: อนุภัทร | E26: ชูเชิด | F26: =D26&" "&E26 -> อนุภัทร ชูเชิด | G26: ANUPAT | H26: CHUCHOED | I26: 10680215 | J26: ทำงานอยู่ | K26: 19/1/2026 | L26: รายวัน | M26: ใช่ | N26: ไม่ใช่ | O26: 18/5/2026 | P26: // | Q26: 10358476 | R26: ผู้ปฎิบัติการ (จ่ายชิ้นส่วน-D) | S26: งานคลังสินค้า | T26: โรงงานชำแหละและตัดแต่งสุกรพระพุทธบาท | U26: Phra Phutthabat | V26: Saraburi | W26: ไทย | X26: 1 | Y26: คลัง | AB26: จ่ายชิ้นส่วนกะ | AC26: จ | AF26: กะ2 | AL26: 0.75 | AM26: 0.125 | AN26: 0.29166667
A27: 205 | B27: 10634228 | C27: นางสาว | D27: สุภัทร์ตรา | E27: ยามสุข | F27: =D27&" "&E27 -> สุภัทร์ตรา ยามสุข | G27: SUPATTRA | H27: YAMSUK | I27: 10634228 | J27: ทำงานอยู่ | K27: 19/1/2025 | L27: รายวัน | M27: ใช่ | N27: ใช่ | O27: 18/5/2025 | P27: 18/5/2025 | Q27: 10358486 | R27: ผู้ปฏิบัติการ (จ่ายชิ้นส่วน-D) | S27: งานคลังสินค้า | T27: โรงงานชำแหละและตัดแต่งสุกรพระพุทธบาท | U27: Phra Phutthabat | V27: Saraburi | W27: ไทย | X27: 1 | Y27: คลัง | AB27: จ่ายชิ้นส่วนกะ | AC27: จ | AF27: กะ2 | AL27: 0.75 | AM27: 0.125 | AN27: 0.29166667
A28: 293 | B28: 10664114 | C28: นาย | D28: ศุภชัย | E28: เที่ยงตรง | F28: =D28&" "&E28 -> ศุภชัย เที่ยงตรง | G28: SUPACHAI | H28: TAENGTONG | I28: 10664114 | J28: ทำงานอยู่ | K28: 45878 | L28: รายวัน | M28: ใช่ | N28: ใช่ | O28: 46143 | P28: 46143 | Q28: 10358486 | R28: ผู้ปฏิบัติการ (จ่ายชิ้นส่วน-D) | S28: งานคลังสินค้า | T28: โรงงานชำแหละและตัดแต่งสุกรพระพุทธบาท | U28: Phra Phutthabat | V28: Saraburi | W28: ไทย | X28: 1 | Y28: คลัง | AB28: จ่ายชิ้นส่วนกะ | AC28: อา | AF28: กะ2 | AL28: 0.75 | AM28: 0.125 | AN28: 0.29166667
A29: 55 | B29: 10400672 | C29: นางสาว | D29: วิภารัตน์ | E29: เมืองสวัสดิ์ | F29: =D29&" "&E29 -> วิภารัตน์ เมืองสวัสดิ์ | G29: WIPARAT | H29: MUENGSAWAT | I29: 10400672 | J29: ทำงานอยู่ | K29: 43866 | L29: รายวัน | M29: ใช่ | N29: ใช่ | O29: 29/8/2020 | P29: 29/8/2020 | Q29: 10358486 | R29: ผู้ปฏิบัติการ (จ่ายชิ้นส่วน-D) | S29: งานคลังสินค้า | T29: โรงงานชำแหละและตัดแต่งสุกรพระพุทธบาท | U29: Phra Phutthabat | V29: Saraburi | W29: ไทย | X29: 1 | Y29: คลัง | AB29: จ่ายชิ้นส่วนกะ | AC29: พฤ | AF29: กะ2 | AL29: 0.75 | AM29: 0.125 | AN29: 0.29166667
B30: 10567884 | D30: รชานนท์ | E30: นาเจริญ | S30: งานคลังสินค้า | AB30: จ่ายชิ้นส่วนกะ | AC30: พ | AF30: กะ2 | AL30: 0.75 | AM30: 0.125 | AN30: 0.29166667
B31: 10625418 | D31: ธีรนัย | E31: ชุลวงศ์ | S31: งานคลังสินค้า | AB31: จ่ายชิ้นส่วนกะ | AC31: อ | AF31: กะ2 | AL31: 0.75 | AM31: 0.125 | AN31: 0.29166667
A32: 165 | B32: 10601105 | C32: นาย | D32: ธนูทรัพย์ | E32: กองปัญญา | F32: =D32&" "&E32 -> ธนูทรัพย์ กองปัญญา | G32: THANUSAP | H32: KONGPANYA | I32: 10601105 | J32: ทำงานอยู่ | K32: 16/3/2024 | L32: รายวัน | M32: ใช่ | N32: ใช่ | O32: 13/7/2024 | P32: 13/7/2024 | Q32: 10358486 | R32: ผู้ปฏิบัติการ (จ่ายชิ้นส่วน-D) | S32: งานคลังสินค้า | T32: โรงงานชำแหละและตัดแต่งสุกรพระพุทธบาท | U32: Phra Phutthabat | V32: Saraburi | W32: ไทย | X32: 1 | Y32: คลัง | AB32: จ่ายชิ้นส่วนกะ | AC32: ส | AF32: กะ2 | AL32: 0.75 | AM32: 0.125 | AN32: 0.29166667
A33: 54 | B33: 10400670 | C33: นาย | D33: ณัฐพล | E33: ทองจันทร์ | F33: =D33&" "&E33 -> ณัฐพล ทองจันทร์ | G33: NATTAPON | H33: THONGJUN | I33: 10400670 | J33: ทำงานอยู่ | K33: 43866 | L33: รายวัน | M33: ใช่ | N33: ใช่ | O33: 29/8/2020 | P33: 29/8/2020 | Q33: 10358486 | R33: ผู้ปฏิบัติการ (จ่ายชิ้นส่วน-D) | S33: งานคลังสินค้า | T33: โรงงานชำแหละและตัดแต่งสุกรพระพุทธบาท | U33: Phra Phutthabat | V33: Saraburi | W33: ไทย | X33: 1 | Y33: คลัง | AB33: จ่ายชิ้นส่วนกะ | AC33: พฤ | AF33: กะ2 | AL33: 0.75 | AM33: 0.125 | AN33: 0.29166667
A34: 130 | B34: 10545025 | C34: นาย | D34: ณัฐพล | E34: รามัญ | F34: =D34&" "&E34 -> ณัฐพล รามัญ | G34: NATTHAPHON | H34: RAMAN | I34: 10545025 | J34: ทำงานอยู่ | K34: 16/2/2023 | L34: รายวัน | M34: ใช่ | N34: ใช่ | O34: 15/6/2023 | P34: 15/6/2023 | Q34: 10358486 | R34: ผู้ปฏิบัติการ (จ่ายชิ้นส่วน-D) | S34: งานคลังสินค้า | T34: โรงงานชำแหละและตัดแต่งสุกรพระพุทธบาท | U34: Phra Phutthabat | V34: Saraburi | W34: ไทย | X34: 1 | Y34: คลัง | AB34: จ่ายชิ้นส่วนกะ | AC34: อา | AF34: กะ2 | AL34: 0.75 | AM34: 0.125 | AN34: 0.29166667
A35: 187 | B35: 10609778 | C35: นาย | D35: อภิชัย | E35: พิมพ์สุวรรณ | F35: =D35&" "&E35 -> อภิชัย พิมพ์สุวรรณ | G35: APHICHAI | H35: PHIMSUWAN | I35: 10609778 | J35: ทำงานอยู่ | K35: 24/5/2024 | L35: รายวัน | M35: ใช่ | N35: ใช่ | O35: 20/9/2024 | P35: 20/9/2024 | Q35: 10358486 | R35: ผู้ปฏิบัติการ (จ่ายชิ้นส่วน-D) | S35: งานคลังสินค้า | T35: โรงงานชำแหละและตัดแต่งสุกรพระพุทธบาท | U35: Phra Phutthabat | V35: Saraburi | W35: ไทย | X35: 1 | Y35: คลัง | AB35: จ่ายชิ้นส่วนกะ | AC35: ส | AF35: กะ3 | AO35: 0.79166667 | AP35: 0.16666667
A36: 179 | B36: 10606781 | C36: นาย | D36: พีรพัฒน์ | E36: สุขพันธ์ | F36: =D36&" "&E36 -> พีรพัฒน์ สุขพันธ์ | G36: PERAPHANTS | H36: SUKPHANT | I36: 10606781 | J36: ทำงานอยู่ | K36: 45327 | L36: รายวัน | M36: ใช่ | N36: ใช่ | O36: 29/8/2024 | P36: 29/8/2024 | Q36: 10358486 | R36: ผู้ปฏิบัติการ (จ่ายชิ้นส่วน-D) | S36: งานคลังสินค้า | T36: โรงงานชำแหละและตัดแต่งสุกรพระพุทธบาท | U36: Phra Phutthabat | V36: Saraburi | W36: ไทย | X36: 1 | Y36: คลัง | AB36: จ่ายชิ้นส่วนกะ | AC36: ส | AF36: กะ3 | AO36: 0.79166667 | AP36: 0.16666667
A37: 192 | B37: 10619221 | C37: นาย | D37: พงศกร | E37: ชัยประเสริฐ | F37: =D37&" "&E37 -> พงศกร ชัยประเสริฐ | G37: PHONGSAKON | H37: CHAIPRASERT | I37: 10619221 | J37: ทำงานอยู่ | K37: 45299 | L37: รายวัน | M37: ใช่ | N37: ใช่ | O37: 28/11/2024 | P37: 28/11/2024 | Q37: 10358486 | R37: ผู้ปฏิบัติการ (จ่ายชิ้นส่วน-D) | S37: งานคลังสินค้า | T37: โรงงานชำแหละและตัดแต่งสุกรพระพุทธบาท | U37: Phra Phutthabat | V37: Saraburi | W37: ไทย | X37: 1 | Y37: คลัง | AB37: จ่ายชิ้นส่วนกะ | AC37: พ | AF37: กะ3 | AO37: 0.79166667 | AP37: 0.16666667
B38: 10639755 | D38: บุญหลง | E38: เจริญธรรม | S38: งานคลังสินค้า | AB38: จ่ายชิ้นส่วนกะ | AC38: อา | AF38: กะ3 | AO38: 0.79166667 | AP38: 0.16666667
A39: 201 | B39: 10629908 | C39: นาย | D39: ธนาธรณ์ | E39: ใยทอง | F39: =D39&" "&E39 -> ธนาธรณ์ ใยทอง | G39: THANATORN | H39: YAITHONG | I39: 10629908 | J39: ทำงานอยู่ | K39: 25/11/2024 | L39: รายวัน | M39: ใช่ | N39: ใช่ | O39: 24/3/2025 | P39: 24/3/2025 | Q39: 10358486 | R39: ผู้ปฏิบัติการ (จ่ายชิ้นส่วน-D) | S39: งานคลังสินค้า | T39: โรงงานชำแหละและตัดแต่งสุกรพระพุทธบาท | U39: Phra Phutthabat | V39: Saraburi | W39: ไทย | X39: 1 | Y39: คลัง | AB39: จ่ายชิ้นส่วนกะ | AC39: อ | AF39: กะ3 | AO39: 0.79166667 | AP39: 0.16666667
A40: 85 | B40: 10432003 | C40: นาย | D40: จักรพงษ์ | E40: ผลมะขาม | F40: =D40&" "&E40 -> จักรพงษ์ ผลมะขาม | G40: JAKKAPONG | H40: PHOLMAKHAM | I40: 10432003 | J40: ทำงานอยู่ | K40: 44205 | L40: รายวัน | M40: ใช่ | N40: ใช่ | O40: 29/12/2021 | P40: 29/12/2021 | Q40: 10358486 | R40: ผู้ปฏิบัติการ (จ่ายชิ้นส่วน-D) | S40: งานคลังสินค้า | T40: โรงงานชำแหละและตัดแต่งสุกรพระพุทธบาท | U40: Phra Phutthabat | V40: Saraburi | W40: ไทย | X40: 1 | Y40: คลัง | AB40: จ่ายชิ้นส่วนกะ | AC40: จ | AF40: กะ3 | AO40: 0.79166667 | AP40: 0.16666667
...

Sheet Note
B2: สลับกะกันวันไหน กลางวัน / กลาคืน | C2: วันพระ?
B4: เวลาเริ่มกะเท่ากันทุกวันมั้ย

Sheet skill_metrix
A1: emp_id | B1: name | C1: skill | D1: level | E1: can_do
A2: 10029242 | B2: ภัทรพงษ์ มงคล | C2: ออฟฟิศ | D2: 3 | E2: 1
A3: 10039734 | B3: ศุภชัย สามัคคี | C3: ออฟฟิศ | D3: 3 | E3: 1
A4: 10150255 | B4: ชัยยันต์ ชุมกูล | C4: ออฟฟิศ | D4: 3 | E4: 1
A5: 10169542 | B5: ประไพ โพธิ์สี | C5: วางแผน Ordering | D5: 3 | E5: 1
A6: 10249292 | B6: นปภา แซ่เลี้ยว | C6: เชือดสุกร | D6: 3 | E6: 1
A7: 10251629 | B7: ภัทรพงษ์ ภากร | C7: คลัง จ่ายชิ้นส่วน | D7: 3 | E7: 1
A8: 10251629 | B8: ภัทรพงษ์ ภากร | C8: คลัง เครื่องใน | D8: 3 | E8: 1
A9: 10290692 | B9: ธิราทิพย์ นิยมทอง | C9: เปิดหมู(เบสิค) | D9: 3 | E9: 1
A10: 10291674 | B10: วราพร เขียวสี | C10: สุข ผลิต ตัดแต่ง(2) | D10: 3 | E10: 1
A11: 10296449 | B11: วรรณา นิลคูหา | C11: สามชั้น(พิเศษ) | D11: 3 | E11: 1
A12: 10303959 | B12: นพดล มุขดารา | C12: คลัง จ่ายชิ้นส่วน | D12: 3 | E12: 1
A13: 10320337 | B13: จักรกริช อิ่นคำ | C13: พัสดุ | D13: 3 | E13: 1
... A324: 10691741 | B324: KYAW WIN HTAY - | C324: เครื่องในขาว | D324: 3 | E324: 1

Sheet Sheet1
C1: 10361555 | D1: ไหล่ / บด (พิเศษ) | H1: 10357224 | I1: เปิดหมู(เบสิค) | J1: อา | L1: 10500453 | M1: เผาขา/ต้มเลือด | N1: พ | O1: 10643727 | P1: เลาะขา | Q1: พ | R1: 10602917 | S1: สามชั้น(เบสิค) | T1: ศ | U1: มา7.00 | V1: กะ1 | X1: 10359845 | Y1: สไลด์ (เบสิ/พิเศษ) | AA1: อา | AB1: =_xlfn.XLOOKUP(X1,'001-EC-HR-HRBP-Job Information '!B:B,'001-EC-HR-HRBP-Job Information '!S:S) -> งานตัดแต่งพิเศษ
C2: 10653661 | D2: ไหล่ / บด (พิเศษ) | H2: 10500467 | I2: เปิดหมู(เบสิค) | J2: พ | L2: 10500442 | M2: เผาขา/ต้มเลือด | N2: พ | O2: 10643716 | P2: เลาะขา | Q2: พ | R2: 10621533 | S2: สามชั้น(เบสิค) | T2: อ | V2: กะ1 | X2: 10328604 | Y2: สไลด์ (เบสิ/พิเศษ) | AA2: พระ | AB2: =_xlfn.XLOOKUP(X2,'001-EC-HR-HRBP-Job Information '!B:B,'001-EC-HR-HRBP-Job Information '!S:S) -> งานตัดแต่งพิเศษ | AE2: ลำดับที่ | AF2: รหัสพนักงาน | AG2: หน่วยงาน | AH2: ชื่อ-นามสกุล | AI2: วันหยุดประจำสัปดาห์ | AN2: 10526630 | AO2: จริยา สุวรรณโชติ (จิ๊บ) | AP2: พระ | AS2: 10232733 | AT2: เชือด | AW2: 10407392 | AX2: เครื่องในขาว | BA2: 10357224 | BB2: เปิดหมู(เบสิค) | BC2: อา | BE2: สุธิตรี สุรินทร์ | BF2: เครื่องในแดง 1 | BI2: 10501461 | BJ2: สะโพก(เบสิค) | BK2: พ | BL2: 10430354 | BM2: ไหล่(เบสิค) | BN2: พระ | BP2: อภัตรชา เบ็ญจวรรณ | BQ2: เชือด 1 | BS2: รจนา โทยิ้ม | BT2: เครื่องในขาว 1 | BW2: เขมิกา ศิริบาง | BX2: ผ่าซาก 1
C3: 10654256 | D3: ไหล่ / บด (พิเศษ) | H3: 10572343 | I3: เปิดหมู(เบสิค) | J3: ส | L3: 10602919 | M3: เผาขา/ต้มเลือด | N3: พฤ | O3: 10660705 | P3: เลาะขา | Q3: จ | R3: 10653643 | S3: สามชั้น(เบสิค) | T3: ศ | V3: กะ1 | X3: 10407322 | Y3: สไลด์ (เบสิ/พิเศษ) | AA3: พ | AB3: =_xlfn.XLOOKUP(X3,'001-EC-HR-HRBP-Job Information '!B:B,'001-EC-HR-HRBP-Job Information '!S:S) -> งานตัดแต่งพิเศษ | AE3: 1 | AF3: 10545042 | AG3: สำนักงาน | AH3: เกวลิน สาระ (พลอย) | AI3: ส. | AJ3: =_xlfn.XLOOKUP(AF3,'001-EC-HR-HRBP-Job Information '!B:B,'001-EC-HR-HRBP-Job Information '!S:S,"") -> งานคลังสินค้า | AN3: 10539767 | AO3: ธนนันท์ เดชเสริมศรี (ดี้) | AP3: พระ | AS3: 10654262 | AT3: เชือด | AW3: 10407375 | AX3: เครื่องในขาว | BA3: 10500467 | BB3: เปิดหมู(เบสิค) | BC3: พ | BE3: น้ำหอม สิงหะ | BF3: เครื่องในแดง 1 | BI3: 10656662 | BJ3: สะโพก(เบสิค) | BK3: อา | BL3: 10635321 | BM3: ไหล่(เบสิค) | BN3: ส | BP3: สุรเชษฐ แก้วนก | BQ3: เชือด 1 | BS3: สายฝน สังข์หอย | BT3: เครื่องในขาว 1 | BW3: อุทิศ โพธิ์ทอง | BX3: ผ่าซาก 1
C4: 10660438 | D4: ไหล่ / บด (พิเศษ) | H4: 10510242 | I4: เปิดหมู(เบสิค) | J4: จ | L4: 10631670 | M4: เผาขา/ต้มเลือด | N4: ศ | O4: 10661894 | P4: เลาะขา | Q4: พฤ | R4: 10433259 | S4: สามชั้น(เบสิค) | T4: อ | V4: กะ1 | X4: 10338152 | Y4: สไลด์ (เบสิ/พิเศษ) | AA4: พ | AB4: =_xlfn.XLOOKUP(X4,'001-EC-HR-HRBP-Job Information '!B:B,'001-EC-HR-HRBP-Job Information '!S:S) -> งานตัดแต่งพิเศษ | AE4: 2 | AF4: 10668850 | AG4: สำนักงาน | AH4: รสิตา วรอรรถ (เครป) | AI4: ศ. | AJ4: =_xlfn.XLOOKUP(AF4,'001-EC-HR-HRBP-Job Information '!B:B,'001-EC-HR-HRBP-Job Information '!S:S,"") | AN4: 10653675 | AO4: กิตติชัย ดีคำไฮ (อังกอร์) | AP4: อาทิตย์ | AS4: 10656602 | AT4: เชือด | AW4: 10540154 | AX4: เครื่องในขาว | BA4: 10572343 | BB4: เปิดหมู(เบสิค) | BC4: ส | BE4: รัตติกาล จั่นเสือ | BF4: เครื่องในแดง 1 | BI4: 10343714 | BJ4: สะโพก(เบสิค) | BK4: พฤ | BL4: 10539726 | BM4: ไหล่(เบสิค) | BN4: อา | BP4: ศราวุธ ศิริรวง | BQ4: เชือด 1 | BS4: วันชัย คัมภิรานนท์ | BT4: เครื่องในขาว 1 | BW4: ชนธิชา ปัดทะสี | BX4: ผ่าซาก 1
C5: 10661976 | D5: ไหล่ / บด (พิเศษ) | H5: 10410604 | I5: เปิดหมู(เบสิค) | J5: อ | L5: 10654251 | M5: เผาขา/ต้มเลือด | N5: จ | O5: 10668232 | P5: เลาะขา | Q5: อา | R5: 10506552 | S5: สามชั้น(เบสิค) | T5: ส | V5: กะ1 | X5: 10500405 | Y5: สไลด์ (เบสิ/พิเศษ) | AA5: จ | AB5: =_xlfn.XLOOKUP(X5,'001-EC-HR-HRBP-Job Information '!B:B,'001-EC-HR-HRBP-Job Information '!S:S) -> งานตัดแต่งพิเศษ | AE5: 3 | AF5: 10561973 | AG5: สำนักงาน | AH5: ชนะพล ก๊กพิทักษ์ (อ๊อฟ) | AI5: พระ | AJ5: =_xlfn.XLOOKUP(AF5,'001-EC-HR-HRBP-Job Information '!B:B,'001-EC-HR-HRBP-Job Information '!S:S,"") -> งานคลังสินค้า | AN5: 10539774 | AO5: ศราวุธ สุทชา (อาร์ท) | AP5: พระ | AS5: 10680946 | AT5: เชือด | AW5: 10606803 | AX5: เครื่องในขาว | BA5: 10510242 | BB5: เปิดหมู(เบสิค) | BC5: จ | BE5: วณิชา ปนอารีย์ | BF5: เครื่องในแดง 1 | BI5: 10503739 | BJ5: สะโพก(เบสิค) | BK5: จ | BL5: 10659413 | BM5: ไหล่(เบสิค) | BN5: ส | BP5: ศราวุธ ขวัญเมือง | BQ5: เชือด 1 | BS5: อรอุมา ชัชวงษ์ | BT5: เครื่องในขาว 1 | BW5: พิเพชฐ สุขเลี้ยง | BX5: ผ่าซาก 1
C6: 10666855 | D6: ไหล่ / บด (พิเศษ) | H6: 10659529 | I6: เปิดหมู(เบสิค) | J6: อา | L6: 10656683 | M6: เผาขา/ต้มเลือด | N6: จ | O6: 10680150 | P6: เลาะขา | Q6: อา | R6: 10290692 | S6: สามชั้น(เบสิค) | T6: ส | V6: กะ1 | X6: 10550759 | Y6: สไลด์ (เบสิ/พิเศษ) | AA6: ศ | AB6: =_xlfn.XLOOKUP(X6,'001-EC-HR-HRBP-Job Information '!B:B,'001-EC-HR-HRBP-Job Information '!S:S) -> งานตัดแต่งพิเศษ | AE6: 4 | AF6: 10339980 | AG6: picking | AH6: สุดารัตน์ สิงห์กล้า (เม่น) | AI6: อ. | AJ6: =_xlfn.XLOOKUP(AF6,'001-EC-HR-HRBP-Job Information '!B:B,'001-EC-HR-HRBP-Job Information '!S:S,"") -> งานคลังสินค้า | AN6: 10392237 | AO6: ศิกวัส ภู่พัฒน์ (แมต) | AP6: พระ | AS6: 10685996 | AT6: เชือด | AW6: 10604122 | AX6: เครื่องในขาว | BA6: 10410604 | BB6: เปิดหมู(เบสิค) | BC6: อ | BE6: กฤษดา คลังทรัพย์ | BF6: เครื่องในแดง 1 | BI6: 10635312 | BJ6: สะโพก(เบสิค) | BK6: ส | BL6: 10506554 | BM6: ไหล่(เบสิค) | BN6: อา | BP6: สมยศ เม่นน้อย | BQ6: เชือด 1 | BS6: TAI SIM | BT6: เครื่องในขาว 1 | BW6: นำโชค สุขเลี้ยง | BX6: ผ่าซาก 1
C7: 10668111 | D7: ไหล่ / บด (พิเศษ) | H7: 10606791 | I7: เปิดหมู(เบสิค) | J7: พฤ | L7: 10511854 | M7: เผาขา/ต้มเลือด | N7: ศ | O7: 10685891 | P7: เลาะขา | Q7: ศ | R7: 10643191 | S7: สามชั้น(เบสิค) | T7: อา | V7: กะ1 | X7: 10627576 | Y7: สไลด์ (เบสิ/พิเศษ) | AA7: อา | AB7: =_xlfn.XLOOKUP(X7,'001-EC-HR-HRBP-Job Information '!B:B,'001-EC-HR-HRBP-Job Information '!S:S) -> งานตัดแต่งพิเศษ | AE7: 5 | AF7: 10393693 | AG7: picking | AH7: ธมนพัชร์ วงศ์สุนันท์ (ติ๊ก) | AI7: ศ. | AJ7: =_xlfn.XLOOKUP(AF7,'001-EC-HR-HRBP-Job Information '!B:B,'001-EC-HR-HRBP-Job Information '!S:S,"") -> งานคลังสินค้า | AN7: 10680550 | AO7: ดรุณี แถวทับ | AP7: ศุกร์ | AS7: 10659600 | AT7: เชือด | AW7: 10680161 | AX7: เครื่องในขาว | BA7: 10659529 | BB7: เปิดหมู(เบสิค) | BC7: อา | BE7: พัณณ์ชิตา ตั้งชัยวรรณา | BF7: เครื่องในแดง 1 | BI7: 10653664 | BJ7: สะโพก(เบสิค) | BK7: จ | BL7: 10659414 | BM7: ไหล่(เบสิค) | BN7: จ | BP7: SETH TORNG | BQ7: เชือด 1 | BS7: ชลธิชา ศรีทองสุก | BT7: เครื่องในขาว 1 | BW7: ภูวดล หงส์ประสิทธิ์ | BX7: ผ่าซาก 1
C8: 10668189 | D8: ไหล่ / บด (พิเศษ) | H8: 10659516 | I8: เปิดหมู(เบสิค) | J8: จ | L8: 10646376 | M8: เผาขา/ต้มเลือด | N8: อ | O8: 10695580 | P8: เลาะขา | Q8: อ | R8: 10668106 | S8: สามชั้น(เบสิค) | T8: พ | V8: กะ1 | X8: 10661918 | Y8: สไลด์ (เบสิ/พิเศษ) | AA8: อา | AB8: =_xlfn.XLOOKUP(X8,'001-EC-HR-HRBP-Job Information '!B:B,'001-EC-HR-HRBP-Job Information '!S:S) -> งานตัดแต่งพิเศษ | AE8: 6 | AF8: 10386416 | AG8: picking | AH8: โชติกา นาคสุทธิ์ (กิ๊ฟ) | AI8: พฤ. | AJ8: =_xlfn.XLOOKUP(AF8,'001-EC-HR-HRBP-Job Information '!B:B,'001-EC-HR-HRBP-Job Information '!S:S,"") -> งานคลังสินค้า | AN8: 10558894 | AO8: นภาพร สุรินทร์ (เกด) | AP8: อาทิตย์ | AS8: 10546592 | AT8: เชือด | AW8: 10680559 | AX8: เครื่องในขาว | BA8: 10606791 | BB8: เปิดหมู(เบสิค) | BC8: พฤ | BE8: นัสฐา จันทราศรี | BF8: เครื่องในแดง 1 | BI8: 10572347 | BJ8: สะโพก(เบสิค) | BK8: ส | BL8: 10621544 | BM8: ไหล่(เบสิค) | BN8: อา | BP8: LA LAM | BQ8: เชือด 1 | BS8: ศิริวรรณ มัทราช | BT8: เครื่องในขาว 1 | BW8: กำธร บัวเล็ก | BX8: ผ่าซาก 1
C9: 10668259 | D9: ไหล่ / บด (พิเศษ) | H9: 10667006 | I9: เปิดหมู(เบสิค) | J9: พ | L9: 10668118 | M9: เผาขา/ต้มเลือด | N9: อา | R9: 10429682 | S9: สามชั้น(เบสิค) | T9: อ | V9: กะ1 | X9: 10661966 | Y9: สไลด์ (เบสิ/พิเศษ) | AA9: ส | AB9: =_xlfn.XLOOKUP(X9,'001-EC-HR-HRBP-Job Information '!B:B,'001-EC-HR-HRBP-Job Information '!S:S) -> งานตัดแต่งพิเศษ | AE9: 7 | AF9: 10558877 | AG9: picking | AH9: ณัฐพร ทัพศาสตร์ (นัฐ) | AI9: จ. | AJ9: =_xlfn.XLOOKUP(AF9,'001-EC-HR-HRBP-Job Information '!B:B,'001-EC-HR-HRBP-Job Information '!S:S,"") -> งานคลังสินค้า | AN9: 10621537 | AO9: เบญจมาส โพธิ์ศรี (เก่ง) | AP9: พระ | AS9: 10604067 | AT9: เชือด | AW9: 10681978 | AX9: เครื่องในขาว | BA9: 10659516 | BB9: เปิดหมู(เบสิค) | BC9: จ | BE9: ดาวเรือง นาคสังข์ | BF9: เครื่องในแดง 2 | BI9: 10656647 | BJ9: สะโพก(เบสิค) | BK9: อา | BL9: 10656693 | BM9: ไหล่(เบสิค) | BN9: ศ | BP9: นายเติม ขวัญเมือง | BQ9: เชือด 1 | BS9: วิมลรัตน์ เมืองสวัส | BT9: เครื่องในขาว 1 | BW9: MR. KYAW THU SOE | BX9: ผ่าซาก 1
C10: 10668269 | D10: ไหล่ / บด (พิเศษ) | H10: 10666827 | I10: เปิดหมู(เบสิค) | J10: ศ | L10: 10668170 | M10: เผาขา/ต้มเลือด | N10: ส | R10: 10572344 | S10: สามชั้น(เบสิค) | T10: พฤ | V10: กะ1 | X10: 10662725 | Y10: สไลด์ (เบสิ/พิเศษ) | AA10: อ | AB10: =_xlfn.XLOOKUP(X10,'001-EC-HR-HRBP-Job Information '!B:B,'001-EC-HR-HRBP-Job Information '!S:S) -> งานตัดแต่งพิเศษ | AE10: 8 | AF10: 10341299 | AG10: ตะกร้า | AH10: สุดาภรณ์ วงษ์เซ็น (กาน) | AI10: พ. | AJ10: =_xlfn.XLOOKUP(AF10,'001-EC-HR-HRBP-Job Information '!B:B,'001-EC-HR-HRBP-Job Information '!S:S,"") -> งานคลังสินค้า | AN10: 10392242 | AO10: นพพร คำจำรูญ (คะนิ้ง) | AP10: พระ | AS10: 10691696 | AT10: เชือด | AW10: 10688411 | AX10: เครื่องในขาว | BA10: 10667006 | BB10: เปิดหมู(เบสิค) | BC10: พ | BE10: นายพีรวัฒน์ สีสอน | BF10: เครื่องในแดง 2 | BI10: 10659431 | BJ10: สะโพก(เบสิค) | BK10: พ | BL10: 10546803 | BM10: ไหล่(เบสิค) | BN10: พ | BP10: MR. NYI NYI NAING | BQ10: เชือด 1 | BS10: ศิริพร เอี่ยมเจริญ | BT10: เครื่องในขาว 1 | BW10: ขนิษฐา แนบเนียน | BX10: ผ่าซาก 1
C11: 10668132 | D11: ไหล่ / บด (พิเศษ) | H11: 10668237 | I11: เปิดหมู(เบสิค) | J11: อ | L11: 10643202 | M11: เผาขา/ต้มเลือด | N11: อา | R11: 10425241 | S11: สามชั้น(เบสิค) | T11: พ | V11: กะ1 | X11: 10662755 | Y11: สไลด์ (เบสิ/พิเศษ) | AA11: อ | AB11: =_xlfn.XLOOKUP(X11,'001-EC-HR-HRBP-Job Information '!B:B,'001-EC-HR-HRBP-Job Information '!S:S) -> งานตัดแต่งพิเศษ | AE11: 9 | AF11: 10400674 | AG11: ตะกร้า | AH11: ณัฐพล เคลือบด้วง (เซ็นส์) | AI11: พฤ. | AJ11: =_xlfn.XLOOKUP(AF11,'001-EC-HR-HRBP-Job Information '!B:B,'001-EC-HR-HRBP-Job Information '!S:S,"") -> งานคลังสินค้า | AN11: 10590628 | AO11: สุภาพร คำประดิษฐ (ส้ม) | AP11: อังคาร | AS11: 10691699 | AT11: เชือด | AW11: 10691704 | AX11: เครื่องในขาว | BA11: 10666827 | BB11: เปิดหมู(เบสิค) | BC11: ศ | BE11: อมลรัตน์ คำนิสา | BF11: เครื่องในแดง 2 | BI11: 10652122 | BJ11: สะโพก(เบสิค) | BK11: อา | BL11: 10546756 | BM11: ไหล่(เบสิค) | BN11: พ | BP11: MR. PYAE PHYO AUNG | BQ11: เชือด 1 | BS11: MISS SANDAR WIN | BT11: เครื่องในขาว 1 | BW11: ภัษณุ เขาทอง | BX11: ผ่าซาก 1
C12: 10685866 | D12: ไหล่ / บด (พิเศษ) | H12: 10668211 | I12: เปิดหมู(เบสิค) | J12: ศ | R12: 10661955 | S12: สามชั้น(เบสิค) | T12: ส | V12: กะ1 | X12: 10664048 | Y12: สไลด์ (เบสิ/พิเศษ) | AA12: ศ | AB12: =_xlfn.XLOOKUP(X12,'001-EC-HR-HRBP-Job Information '!B:B,'001-EC-HR-HRBP-Job Information '!S:S) -> งานตัดแต่งพิเศษ | AE12: 10 | AF12: 10412335 | AG12: ตะกร้า | AH12: สุกัญญา มั่นชื่น (เปา) | AI12: จ. | AJ12: =_xlfn.XLOOKUP(AF12,'001-EC-HR-HRBP-Job Information '!B:B,'001-EC-HR-HRBP-Job Information '!S:S,"") -> งานคลังสินค้า | AN12: 10688343 | AO12: วิรัชยาภรณ์ บุญเรือง (เดียร์) | AP12: จันทร์ | AS12: 10417544 | AT12: เชือด | AW12: 10691693 | AX12: เครื่องในขาว | BA12: 10668237 | BB12: เปิดหมู(เบสิค) | BC12: อ | BE12: สุนิศา เอนกวัฒน์ | BF12: เครื่องในแดง 2 | BI12: 10660684 | BJ12: สะโพก(เบสิค) | BK12: พฤ | BL12: 10604117 | BM12: ไหล่(เบสิค) | BN12: ศ | BP12: สราวุธ โต้ตอบ | BQ12: เชือด 1 | BS12: MISS NAN KHIN MYO SAN | BT12: เครื่องในขาว 1 | BW12: ณรงค์ฤทธิ์ พรมจารีย | BX12: ผ่าซาก 1
C13: 10685901 | D13: ไหล่ / บด (พิเศษ) | H13: 10675928 | I13: เปิดหมู(เบสิค) | J13: พฤ | R13: 10685880 | S13: สามชั้น(เบสิค) | T13: ศ | U13: มา7.00 | V13: กะ1 | X13: 10668218 | Y13: สไลด์ (เบสิ/พิเศษ) | AA13: พฤ | AB13: =_xlfn.XLOOKUP(X13,'001-EC-HR-HRBP-Job Information '!B:B,'001-EC-HR-HRBP-Job Information '!S:S) -> งานตัดแต่งพิเศษ | AE13: 11 | AF13: 10641165 | AG13: ตะกร้า | AH13: พรวดี วงษ์เซ็น (เพลง) | AI13: อ. | AJ13: =_xlfn.XLOOKUP(AF13,'001-EC-HR-HRBP-Job Information '!B:B,'001-EC-HR-HRBP-Job Information '!S:S,"") -> งานคลังสินค้า | AN13: 10688526 | AO13: สุนิษา ฉลยมนต์ (แฟง) | AP13: พุธ | AS13: 10656584 | AT13: เชือด | BA13: 10668211 | BB13: เปิดหมู(เบสิค) | BC13: ศ | BE13: MISS SHELL SHELL MHAYIE | BF13: เครื่องในแดง 2 | BI13: 10666845 | BJ13: สะโพก(เบสิค) | BK13: ศ | BL13: 10666798 | BM13: ไหล่(เบสิค) | BN13: จ | BP13: อภิสิทธิ์ คำนิสา | BQ13: เชือด 2 | BS13: วรกพ ชูเกาะ | BT13: เครื่องในขาว 1 | BW13: อ้อยทิพย์ แจ้งสงค์ | BX13: ผ่าซาก 2 | BY13: 16.00-1.00
C14: 10685933 | D14: ไหล่ / บด (พิเศษ) | H14: 10680434 | I14: เปิดหมู(เบสิค) | J14: ส | R14: 10685921 | S14: สามชั้น(เบสิค) | T14: จ | V14: กะ1 | X14: 10668096 | Y14: สไลด์ (เบสิ/พิเศษ) | AA14: พ | AB14: =_xlfn.XLOOKUP(X14,'001-EC-HR-HRBP-Job Information '!B:B,'001-EC-HR-HRBP-Job Information '!S:S) -> งานตัดแต่งพิเศษ | AE14: 12 | AF14: 10643182 | AG14: จ่ายชิ้นส่วนกะ1 | AH14: นัฐพงษ์ ไหวพริบ (นัด) | AI14: อ. | AJ14: =_xlfn.XLOOKUP(AF14,'001-EC-HR-HRBP-Job Information '!B:B,'001-EC-HR-HRBP-Job Information '!S:S,"") -> งานคลังสินค้า | AN14: 10641168 | AO14: พัชราภรณ์ แก้วใส(บีม) | AP14: ศุกร์ | BA14: 10675928 | BB14: เปิดหมู(เบสิค) | BC14: พฤ | BE14: MISS SU MYAT THIN | BF14: เครื่องในแดง 2 | BI14: 10666852 | BJ14: สะโพก(เบสิค) | BK14: ส | BL14: 10666837 | BM14: ไหล่(เบสิค) | BN14: จ | BP14: สัญญา สุขแจ้งแสงทอง | BQ14: เชือด 2 | BS14: สุกัญญา นาร้อยเอ็ด | BT14: เครื่องในขาว 1 | BW14: พรไพลิน ฉายลม | BX14: ผ่าซาก 2
C15: 10617287 | D15: ไหล่ / บด (พิเศษ) | H15: 10680448 | I15: เปิดหมู(เบสิค) | J15: จ | R15: 10685918 | S15: สามชั้น(เบสิค) | T15: อา | V15: กะ1 | X15: 10685895 | Y15: สไลด์ (เบสิ/พิเศษ) | AA15: จ | AB15: =_xlfn.XLOOKUP(X15,'001-EC-HR-HRBP-Job Information '!B:B,'001-EC-HR-HRBP-Job Information '!S:S) -> งานตัดแต่งพิเศษ | AE15: 13 | AF15: 10417544 | AG15: จ่ายชิ้นส่วนกะ1 | AH15: สราวุธ โต้ตอบ (วุธ) | AI15: ศ. | AJ15: =_xlfn.XLOOKUP(AF15,'001-EC-HR-HRBP-Job Information '!B:B,'001-EC-HR-HRBP-Job Information '!S:S,"") -> งานคลังสินค้า | AN15: 10569567 | AO15: พลาพร คชสาร (อุ๋ย) | AP15: เสาร์ | BA15: 10680434 | BB15: เปิดหมู(เบสิค) | BC15: ส | BE15: จีรนุช บุญปารุง | BF15: เครื่องในแดง 2 | BI15: 10675888 | BJ15: สะโพก(เบสิค) | BK15: พฤ | BL15: 10668124 | BM15: ไหล่(เบสิค) | BN15: ส | BP15: LOUCH VON | BQ15: เชือด 2 | BS15: สุกานดา โอระน่า | BT15: เครื่องในขาว 1 | BW15: NAN SARON | BX15: ผ่าซาก 2
H16: 10680424 | I16: เปิดหมู(เบสิค) | J16: อา | X16: 10685985 | Y16: สไลด์ (เบสิ/พิเศษ) | AA16: พฤ | AB16: =_xlfn.XLOOKUP(X16,'001-EC-HR-HRBP-Job Information '!B:B,'001-EC-HR-HRBP-Job Information '!S:S) -> งานตัดแต่งพิเศษ | AE16: 14 | AF16: 10596679 | AG16: จ่ายชิ้นส่วนกะ1 | AH16: สัญญา อนุสิทธิ์ (บอย) | AI16: พ. | AJ16: =_xlfn.XLOOKUP(AF16,'001-EC-HR-HRBP-Job Information '!B:B,'001-EC-HR-HRBP-Job Information '!S:S,"") -> งานคลังสินค้า | AN16: 10602863 | AO16: กมลชนก ภูทอง (ส้ม) | AP16: อาทิตย์ | BA16: 10680448 | BB16: เปิดหมู(เบสิค) | BC16: จ | BI16: 10675910 | BJ16: สะโพก(เบสิค) | BK16: อา | BL16: 10668201 | BM16: ไหล่(เบสิค) | BN16: อ | BP16: CHAMNIT NAI | BQ16: เชือด 2 | BS16: เรณู อุทุมพิรัตน์ | BT16: เครื่องในขาว 2 | BW16: อนันตญา พงเสมา (คนท้อง) | BX16: ผ่าซาก 2
H17: 10660114 | I17: เปิดหมู(เบสิค) | J17: อ | X17: 10695589 | Y17: สไลด์ (เบสิ/พิเศษ) | AA17: อา | AB17: =_xlfn.XLOOKUP(X17,'001-EC-HR-HRBP-Job Information '!B:B,'001-EC-HR-HRBP-Job Information '!S:S) -> งานตัดแต่งพิเศษ | AE17: 15 | AF17: 10634220 | AG17: จ่ายชิ้นส่วนกะ1 | AH17: ปวริศา ภิรมยา (นิว) | AI17: จ. | AJ17: =_xlfn.XLOOKUP(AF17,'001-EC-HR-HRBP-Job Information '!B:B,'001-EC-HR-HRBP-Job Information '!S:S,"") -> งานคลังสินค้า | AN17: 10513272 | AO17: อรัญญา วงษ์ตา (ดาว) | AP17: พฤหัส | BA17: 10680424 | BB17: เปิดหมู(เบสิค) | BC17: อา | BI17: 10680567 | BJ17: สะโพก(เบสิค) | BK17: พ | BL17: 10668228 | BM17: ไหล่(เบสิค) | BN17: พฤ | BP17: RIN HUY | BQ17: เชือด 2 | BS17: กุ้ง อ่างบุญตา | BT17: เครื่องในขาว 2 | BW17: อุมาพร แจ่มจันทร์ | BX17: ผ่าซาก 2
AE18: 16 | AF18: 10641135 | AG18: จ่ายชิ้นส่วนกะ1 | AH18: ทรงยศ เกิดขาว (ยศ) | AI18: พฤ. | AJ18: =_xlfn.XLOOKUP(AF18,'001-EC-HR-HRBP-Job Information '!B:B,'001-EC-HR-HRBP-Job Information '!S:S,"") -> งานคลังสินค้า | AN18: 10604549 | AO18: ชลลดา หมวกเหล็ก (ดรีม) | AP18: เสาร์ | BA18: 10660114 | BB18: เปิดหมู(เบสิค) | BC18: อ | BI18: 10681984 | BJ18: สะโพก(เบสิค) | BK18: อา | BL18: 10666666 | BM18: ไหล่(เบสิค) | BN18: อ | BP18: สมชาย กุลเล็ก | BQ18: เชือด 2 | BS18: HAN YIM | BT18: เครื่องในขาว 2 | BW18: เอกน ดวงรัตน์ | BX18: ผ่าซาก 2
AE19: 17 | AF19: 10652130 | AG19: จ่ายชิ้นส่วนกะ1 | AH19: ชยุต ธาทนะปรีดา (ตั้ม) | AI19: พฤ. | AJ19: =_xlfn.XLOOKUP(AF19,'001-EC-HR-HRBP-Job Information '!B:B,'001-EC-HR-HRBP-Job Information '!S:S,"") -> งานคลังสินค้า | AN19: 10540523 | AO19: ศิรภัสสร บุญยมาลิก (แบม) | AP19: อาทิตย์ | BI19: 10685959 | BJ19: สะโพก(เบสิค) | BK19: พฤ | BL19: 10688403 | BM19: ไหล่(เบสิค) | BN19: พ | BP19: อนุเดช สองใหม่ | BQ19: เชือด 2 | BS19: บุษบา เทพตาแสง | BT19: เครื่องในขาว 2 | BW19: พงศกร สิงห์เสรี | BX19: ผ่าซาก 2
AE20: 18 | AG20: จ่ายชิ้นส่วนกะ1 | AH20: อดิศักดิ์ ผาสุขธรรม(เอก) | AI20: อา. | AJ20: =_xlfn.XLOOKUP(AF20,'001-EC-HR-HRBP-Job Information '!B:B,'001-EC-HR-HRBP-Job Information '!S:S,"") -> 0 | BI20: 10691724 | BJ20: สะโพก(เบสิค) | BK20: ศ | BL20: 10660111 | BM20: ไหล่(เบสิค) | BN20: อ | BP20: ณรงค์ศักดิ์ เสมแก้ว | BQ20: เชือด 2 | BS20: จิราภา มณีสุข | BT20: เครื่องในขาว 2 | BW20: MR. WUNNA THWIN | BX20: ผ่าซาก 2
AE21: 19 | AF21: 10653715 | AG21: จ่ายชิ้นส่วนกะ1 | AH21: ยุทธนา ภูทอง (อ้วน) | AI21: พ. | AJ21: =_xlfn.XLOOKUP(AF21,'001-EC-HR-HRBP-Job Information '!B:B,'001-EC-HR-HRBP-Job Information '!S:S,"") -> งานคลังสินค้า | BP21: ขวัญชัย โพธิ์ปิ่น | BQ21: เชือด 2 | BS21: ปนัดดา ศรีวารี | BT21: เครื่องในขาว 2 | BW21: MR.ZAW MYO AUNG | BX21: ผ่าซาก 2
AE22: 20 | AF22: 10567228 | AG22: จ่ายชิ้นส่วนกะ1 | AH22: อริย เสนาะสลุง (นิว) | AI22: อา. | AJ22: =_xlfn.XLOOKUP(AF22,'001-EC-HR-HRBP-Job Information '!B:B,'001-EC-HR-HRBP-Job Information '!S:S,"") -> งานคลังสินค้า | BP22: สิทธิ์ศักดิ์ สุวรรณ์ | BQ22: เชือด 2 | BS22: สุพัตรา เพรียสมผล | BT22: เครื่องในขาว 2 | BW22: ศิริลักษ์ เนตรสว่าง | BX22: ผ่าซาก 2
AE23: 21 | AF23: 10400670 | AG23: จ่ายชิ้นส่วนกะ2 | AH23: ณัฐพล ทองจันทร์ (ต้น) | AI23: พฤ. | AJ23: =_xlfn.XLOOKUP(AF23,'001-EC-HR-HRBP-Job Information '!B:B,'001-EC-HR-HRBP-Job Information '!S:S,"") -> งานคลังสินค้า | BP23: ยอด ยิ่งจ่าเจริญ | BQ23: เชือด 2 | BS23: YE WAI | BT23: เครื่องในขาว 2 | BW23: SAMNANG LOUCH | BX23: ผ่าซาก 2
AE24: 22 | AF24: 10400672 | AG24: จ่ายชิ้นส่วนกะ2 | AH24: วิภารัตน์ เมืองสวัสดิ์ (แอน) | AI24: พฤ. | AJ24: =_xlfn.XLOOKUP(AF24,'001-EC-HR-HRBP-Job Information '!B:B,'001-EC-HR-HRBP-Job Information '!S:S,"") -> งานคลังสินค้า | BP24: UOCH NOV | BQ24: เชือด 2 | BS24: MYINT SANDAR TUN | BT24: เครื่องในขาว 2
AE25: 23 | AF25: 10601105 | AG25: จ่ายชิ้นส่วนกะ2 | AH25: ธนูทรัพย์ กองปัญญา (นู) | AI25: ส. | AJ25: =_xlfn.XLOOKUP(AF25,'001-EC-HR-HRBP-Job Information '!B:B,'001-EC-HR-HRBP-Job Information '!S:S,"") -> งานคลังสินค้า | BP25: MR. AYAR AUNG | BQ25: เชือด 2 | BS25: KYAW WIN HTAY | BT25: เครื่องในขาว 2
AE26: 24 | AF26: 10545025 | AG26: จ่ายชิ้นส่วนกะ2 | AH26: ณัฐพล รามัญ (บอส) | AI26: อา. | AJ26: =_xlfn.XLOOKUP(AF26,'001-EC-HR-HRBP-Job Information '!B:B,'001-EC-HR-HRBP-Job Information '!S:S,"") -> งานคลังสินค้า | BP26: MR. MG KO KO | BQ26: เชือด 2 | BS26: HNIN NU WAT | BT26: เครื่องในขาว 2
AE27: 25 | AF27: 10567884 | AG27: จ่ายชิ้นส่วนกะ2 | AH27: รชานนท์ นาเจริญ (นนท์) | AI27: พ. | AJ27: =_xlfn.XLOOKUP(AF27,'001-EC-HR-HRBP-Job Information '!B:B,'001-EC-HR-HRBP-Job Information '!S:S,"") -> งานคลังสินค้า
AE28: 26 | AF28: 10625418 | AG28: จ่ายชิ้นส่วนกะ2 | AH28: ธีรนัย ชุลวงศ์ (ที) | AI28: อ. | AJ28: =_xlfn.XLOOKUP(AF28,'001-EC-HR-HRBP-Job Information '!B:B,'001-EC-HR-HRBP-Job Information '!S:S,"") -> งานคลังสินค้า
AE29: 27 | AF29: 10634228 | AG29: จ่ายชิ้นส่วนกะ2 | AH29: สุภัทรตรา ยามสุข (ออย) | AI29: จ. | AJ29: =_xlfn.XLOOKUP(AF29,'001-EC-HR-HRBP-Job Information '!B:B,'001-EC-HR-HRBP-Job Information '!S:S,"") -> งานคลังสินค้า
AE30: 28 | AF30: 10664114 | AG30: จ่ายชิ้นส่วนกะ2 | AH30: ศุภชัย เที่ยงตรง (อ๊อฟ) | AI30: อา. | AJ30: =_xlfn.XLOOKUP(AF30,'001-EC-HR-HRBP-Job Information '!B:B,'001-EC-HR-HRBP-Job Information '!S:S,"") -> งานคลังสินค้า
AE31: 29 | AG31: จ่ายชิ้นส่วนกะ2 | AH31: อนุภัทร ชูเชิด(ฟลุ๊ค) | AI31: จ. | AJ31: =_xlfn.XLOOKUP(AF31,'001-EC-HR-HRBP-Job Information '!B:B,'001-EC-HR-HRBP-Job Information '!S:S,"") -> 0
AE32: 30 | AF32: 10432003 | AG32: จ่ายชิ้นส่วนกะ3 | AH32: จักรพงษ์ ผลมะขาม (แมน) | AI32: จ. | AJ32: =_xlfn.XLOOKUP(AF32,'001-EC-HR-HRBP-Job Information '!B:B,'001-EC-HR-HRBP-Job Information '!S:S,"") -> งานคลังสินค้า
AE33: 31 | AF33: 10619221 | AG33: จ่ายชิ้นส่วนกะ3 | AH33: พงศกร ชัยประเสริฐ (ไฟส์) | AI33: พ. | AJ33: =_xlfn.XLOOKUP(AF33,'001-EC-HR-HRBP-Job Information '!B:B,'001-EC-HR-HRBP-Job Information '!S:S,"") -> งานคลังสินค้า
AE34: 32 | AF34: 10609778 | AG34: จ่ายชิ้นส่วนกะ3 | AH34: อภิชัย พิมพ์วรรณ (โบ๊ท) | AI34: ส. | AJ34: =_xlfn.XLOOKUP(AF34,'001-EC-HR-HRBP-Job Information '!B:B,'001-EC-HR-HRBP-Job Information '!S:S,"") -> งานคลังสินค้า
AE35: 33 | AF35: 10629908 | AG35: จ่ายชิ้นส่วนกะ3 | AH35: ธนาธรณ์ ใยทอง (อาท) | AI35: อ. | AJ35: =_xlfn.XLOOKUP(AF35,'001-EC-HR-HRBP-Job Information '!B:B,'001-EC-HR-HRBP-Job Information '!S:S,"") -> งานคลังสินค้า
AE36: 34 | AF36: 10639755 | AG36: จ่ายชิ้นส่วนกะ3 | AH36: บุญหลง เจริญธรรม (หลง) | AI36: อา. | AJ36: =_xlfn.XLOOKUP(AF36,'001-EC-HR-HRBP-Job Information '!B:B,'001-EC-HR-HRBP-Job Information '!S:S,"") -> งานคลังสินค้า
AE37: 35 | AF37: 10653683 | AG37: จ่ายชิ้นส่วนกะ3 | AH37: กิตติพล บุญครุฑ (แอล) | AI37: ศ. | AJ37: =_xlfn.XLOOKUP(AF37,'001-EC-HR-HRBP-Job Information '!B:B,'001-EC-HR-HRBP-Job Information '!S:S,"") -> งานคลังสินค้า
AE38: 36 | AG38: จ่ายชิ้นส่วนกะ3 | AH38: กนกวรรณ ไตรพรหม(นัท) | AI38: พฤ. | AJ38: =_xlfn.XLOOKUP(AF38,'001-EC-HR-HRBP-Job Information '!B:B,'001-EC-HR-HRBP-Job Information '!S:S,"") -> 0
AE39: 37 | AF39: 10606781 | AG39: จ่ายชิ้นส่วนกะ3 | AH39: พีรพัฒน์ สุขพันธ์ (แฟ้ม) | AI39: ส. | AJ39: =_xlfn.XLOOKUP(AF39,'001-EC-HR-HRBP-Job Information '!B:B,'001-EC-HR-HRBP-Job Information '!S:S,"") -> งานคลังสินค้า
AE40: 38 | AF40: 10419529 | AG40: รับผลได้ชิ้นส่วน กลางวัน | AH40: ธวัชชัย เชนชาญ (กอล์ฟ) | AI40: พ. | AJ40: =_xlfn.XLOOKUP(AF40,'001-EC-HR-HRBP-Job Information '!B:B,'001-EC-HR-HRBP-Job Information '!S:S,"") -> งานคลังสินค้า
...
